<?xml version="1.0"?>
<!-- This URDF was automatically created by SolidWorks to URDF Exporter! Originally created by Stephen Brawner (brawner@gmail.com) 
     Commit Version: 1.6.0-4-g7f85cfe  Build Version: 1.6.7995.38578
     For more information, please see http://wiki.ros.org/sw_urdf_exporter -->

<robot xmlns:xacro="http://www.ros.org/wiki/xacro" >
<xacro:include filename="inertial_macros.xacro"/>
<!-- BASE LINK -->

    <link name="base_link">

    </link>

    <!-- BASE_FOOTPRINT LINK -->

<joint name="base_footprint_joint" type="fixed">
        <parent link="base_link"/>
        <child link="base_footprint"/>
        <origin xyz="0 0 0" rpy="0 0 0"/>
    </joint>

    <link name="base_footprint">
    </link>


    <!-- CHASSIS LINK -->

    <joint name="chassis_joint" type="fixed">
        <parent link="base_link"/>
        <child link="chassis"/>
        <origin xyz="0 0 0"/>
    </joint>

  <link
    name="chassis">
    <inertial>
      <origin
        xyz="-0.011623 0.00031297 0.03414"
        rpy="0 0 0" />
      <mass
        value="1.03" />
      <inertia
        ixx="0.0031032"
        ixy="3.2221E-10"
        ixz="7.7859E-06"
        iyy="0.004193"
        iyz="-3.2649E-05"
        izz="0.0055868" />
    </inertial>
    <visual>
      <origin
        xyz="0 0 0"
        rpy="0 0 0" />
      <geometry>
        <mesh
          filename="package://modelo_robot/meshes/base_link.STL" />
      </geometry>
      <material
        name="">
        <color
          rgba="0.79216 0.81961 0.93333 1" />
      </material>
    </visual>
    <collision>
      <origin
        xyz="0 0 0"
        rpy="0 0 0" />
      <geometry>
        <mesh
          filename="package://modelo_robot/meshes/base_link.STL" />
      </geometry>
    </collision>
  </link>
  
  <gazebo reference="chassis">
    <material>Gazebo/Yellow</material>
  </gazebo>

  <link
    name="rueda_izq_delantera_link">
    <inertial>
      <origin
        xyz="0 0 -0.00031672"
        rpy="0 0 0" />
      <mass
        value="0.72984" />
      <inertia
        ixx="0.00091283"
        ixy="-8.021E-20"
        ixz="-4.0426E-21"
        iyy="0.00091283"
        iyz="-1.7102E-20"
        izz="0.001326" />
    </inertial>
    <visual>
      <origin
        xyz="0 0 0"
        rpy="0 0 0" />
      <geometry>
        <mesh
          filename="package://modelo_robot/meshes/rueda_izq_delantera_link.STL" />
      </geometry>
      <material
        name="">
        <color
          rgba="0.79216 0.81961 0.93333 1" />
      </material>
    </visual>
    <collision>
      <origin
        xyz="0 0 0"
        rpy="0 0 0" />
      <geometry>
        <mesh
          filename="package://modelo_robot/meshes/rueda_izq_delantera_link.STL" />
      </geometry>
    </collision>
  </link>
  <joint
    name="rueda_izq_delantera_joint"
    type="continuous">
    <origin
      xyz="0.097 0.1255 -0.050622"
      rpy="1.5708 0 3.1416" />
    <parent
      link="base_link" />
    <child
      link="rueda_izq_delantera_link" />
    <axis
      xyz="0 0 1" />
    <limit
      effort="100"
      velocity="100" />
    <dynamics
      damping="0.1"
      friction="0.1" />
  </joint>
  
  <gazebo reference="rueda_izq_delantera_link">
    <material>Gazebo/Gray</material>
  </gazebo>
  
  <link
    name="rueda_izq_trasera_link">
    <inertial>
      <origin
        xyz="0 0 -0.00031672"
        rpy="0 0 0" />
      <mass
        value="0.72984" />
      <inertia
        ixx="0.00091283"
        ixy="5.3323E-20"
        ixz="-7.9882E-20"
        iyy="0.00091283"
        iyz="3.104E-21"
        izz="0.001326" />
    </inertial>
    <visual>
      <origin
        xyz="0 0 0"
        rpy="0 0 0" />
      <geometry>
        <mesh
          filename="package://modelo_robot/meshes/rueda_izq_trasera_link.STL" />
      </geometry>
      <material
        name="">
        <color
          rgba="0.79216 0.81961 0.93333 1" />
      </material>
    </visual>
    <collision>
      <origin
        xyz="0 0 0"
        rpy="0 0 0" />
      <geometry>
        <mesh
          filename="package://modelo_robot/meshes/rueda_izq_trasera_link.STL" />
      </geometry>
    </collision>
  </link>
  
  <gazebo reference="rueda_izq_trasera_link">
    <material>Gazebo/Gray</material>
  </gazebo>
  
  <joint
    name="rueda_izq_trasera_joint"
    type="continuous">
    <origin
      xyz="-0.097 0.1255 -0.050622"
      rpy="1.5708 0 3.1416" />
    <parent
      link="base_link" />
    <child
      link="rueda_izq_trasera_link" />
    <axis
      xyz="0 0 1" />
    <limit
      effort="100"
      velocity="100" />
    <dynamics
      damping="0.1"
      friction="0.1" />
  </joint>
  <link
    name="rueda_der_delantera_link">
    <inertial>
      <origin
        xyz="0 0 0.00031672"
        rpy="0 0 0" />
      <mass
        value="0.72984" />
      <inertia
        ixx="0.00091283"
        ixy="-2.8979E-21"
        ixz="-1.0167E-19"
        iyy="0.00091283"
        iyz="-2.7079E-20"
        izz="0.001326" />
    </inertial>
    <visual>
      <origin
        xyz="0 0 0"
        rpy="0 0 0" />
      <geometry>
        <mesh
          filename="package://modelo_robot/meshes/rueda_der_delantera_link.STL" />
      </geometry>
      <material
        name="">
        <color
          rgba="0.79216 0.81961 0.93333 1" />
      </material>
    </visual>
    <collision>
      <origin
        xyz="0 0 0"
        rpy="0 0 0" />
      <geometry>
        <mesh
          filename="package://modelo_robot/meshes/rueda_der_delantera_link.STL" />
      </geometry>
    </collision>
  </link>
  
  <gazebo reference="rueda_der_delantera_link">
    <material>Gazebo/Gray</material>
  </gazebo>
  
  <joint
    name="rueda_der_delantera_joint"
    type="continuous">
    <origin
      xyz="0.097 -0.1255 -0.050622"
      rpy="1.5708 0 3.1416" />
    <parent
      link="base_link" />
    <child
      link="rueda_der_delantera_link" />
    <axis
      xyz="0 0 1" />
    <limit
      effort="100"
      velocity="100" />
    <dynamics
      damping="0.1"
      friction="0.1" />
  </joint>
  
  <link
    name="rueda_der_trasera_link">
    <inertial>
      <origin
        xyz="0 0 0.00031672"
        rpy="0 0 0" />
      <mass
        value="0.72984" />
      <inertia
        ixx="0.00091283"
        ixy="2.3222E-20"
        ixz="-6.9829E-20"
        iyy="0.00091283"
        iyz="6.4782E-20"
        izz="0.001326" />
    </inertial>
    <visual>
      <origin
        xyz="0 0 0"
        rpy="0 0 0" />
      <geometry>
        <mesh
          filename="package://modelo_robot/meshes/rueda_der_trasera_link.STL" />
      </geometry>
      <material
        name="">
        <color
          rgba="0.79216 0.81961 0.93333 1" />
      </material>
    </visual>
    <collision>
      <origin
        xyz="0 0 0"
        rpy="0 0 0" />
      <geometry>
        <mesh
          filename="package://modelo_robot/meshes/rueda_der_trasera_link.STL" />
      </geometry>
    </collision>
  </link>
  
  <gazebo reference="rueda_der_trasera_link">
    <material>Gazebo/Gray</material>
  </gazebo>
  
  <joint
    name="rueda_der_trasera_joint"
    type="continuous">
    <origin
      xyz="-0.097 -0.1255 -0.050622"
      rpy="1.5708 0 3.1416" />
    <parent
      link="base_link" />
    <child
      link="rueda_der_trasera_link" />
    <axis
      xyz="0 0 1" />
    <limit
      effort="100"
      velocity="100" />
    <dynamics
      damping="0.1"
      friction="0.1" />
  </joint>

  <link
    name="aspersor_link">
    <inertial>
      <origin
        xyz="0 0 0"
        rpy="0 0 0" />
      <mass
        value="0.3" />
      <inertia
        ixx="0.001"
        ixy="0"
        ixz="0"
        iyy="0.001"
        iyz="0"
        izz="0.001" />
    </inertial>
    <visual>
      <origin
        xyz="0 0 0"
        rpy="0 0 0" />
      <geometry>
        <mesh
          filename="package://modelo_robot/meshes/aspersor_link.STL" />
      </geometry>
      <material
        name="">
        <color
          rgba="1 1 1 1" />
      </material>
    </visual>
    <collision>
      <origin
        xyz="0 0 0"
        rpy="0 0 0" />
      <geometry>
        <mesh
          filename="package://modelo_robot/meshes/aspersor_link.STL" />
      </geometry>
    </collision>
  </link>

  <gazebo reference="aspersor_link">
    <material>Gazebo/Blue</material>
  </gazebo>

  <joint
    name="aspersor_joint"
    type="revolute">
    <origin
      xyz="-0.1045 0 0.019"
      rpy="1.5708 0 3.1416" />
    <parent
      link="base_link" />
    <child
      link="aspersor_link" />
    <axis
      xyz="0 1 0" />
    <limit
      lower="-1.5707"
      upper="1.5707"
      effort="5"
      velocity="1" />
  </joint>

</robot>